Workbook

Sheet Tổng quan
A1: AUDIT SEO WEBSITE ADTEK.AGENCY
A2: Nguồn: quét tự động toàn bộ URL trong sitemap Yoast (sitemap_index.xml).
A4: Chỉ số | B4: Giá trị
A5: Số URL đã quét | B5: =COUNTA('Chi tiết URL'!A2:A125)
A6: Số URL trả về HTTP 200 | B6: =COUNTIF('Chi tiết URL'!C2:C125,200)
A7: Tổng số vấn đề | B7: =COUNTA('Vấn đề'!A2:A457)
A8: Vấn đề mức Cao | B8: =COUNTIF('Vấn đề'!A2:A457,"Cao")
A9: Vấn đề mức Trung bình | B9: =COUNTIF('Vấn đề'!A2:A457,"Trung bình")
A10: Vấn đề mức Thấp | B10: =COUNTIF('Vấn đề'!A2:A457,"Thấp")
A11: Link nội bộ hỏng | B11: 0 | C11: Đếm từ sheet Link hỏng
A13: Vấn đề | B13: Số URL | C13: Mức độ
A14: Thiếu meta description | B14: =COUNTIF('Vấn đề'!B2:B457,"description_missing") | C14: Cao
A15: Thiếu thẻ H1 | B15: =COUNTIF('Vấn đề'!B2:B457,"h1_missing") | C15: Cao
A16: Trang bị lỗi nghiêm trọng (PHP) giữa chừng | B16: =COUNTIF('Vấn đề'!B2:B457,"server_error") | C16: Cao
A17: Sitemap ghi URL tiếng Anh thành URL tiếng Việt (thiếu /en/) | B17: =COUNTIF('Vấn đề'!B2:B457,"sitemap_wrong_lang_url") | C17: Cao
A18: Meta description trùng với trang khác | B18: =COUNTIF('Vấn đề'!B2:B457,"description_duplicate") | C18: Trung bình
A19: Có nhiều hơn 1 thẻ H1 | B19: =COUNTIF('Vấn đề'!B2:B457,"h1_multiple") | C19: Trung bình
A20: Ảnh trong nội dung thiếu alt | B20: =COUNTIF('Vấn đề'!B2:B457,"img_alt_missing") | C20: Trung bình
A21: Link nội bộ dùng http hoặc URL cũ, phải chuyển hướng | B21: =COUNTIF('Vấn đề'!B2:B457,"link_redirect") | C21: Trung bình
A22: Nội dung mỏng (dưới 300 từ) | B22: =COUNTIF('Vấn đề'!B2:B457,"thin_content") | C22: Trung bình
A23: Meta description dài hơn 160 ký tự | B23: =COUNTIF('Vấn đề'!B2:B457,"description_long") | C23: Thấp
A24: Thiếu ảnh chia sẻ mạng xã hội (og:image) | B24: =COUNTIF('Vấn đề'!B2:B457,"og_image_missing") | C24: Thấp
A25: Title dài hơn 60 ký tự, Google sẽ cắt bớt | B25: =COUNTIF('Vấn đề'!B2:B457,"title_long") | C25: Thấp
A26: Title ngắn hơn 30 ký tự | B26: =COUNTIF('Vấn đề'!B2:B457,"title_short") | C26: Thấp

Sheet Vấn đề
A1: Mức độ | B1: Mã lỗi | C1: Vấn đề | D1: Nhóm | E1: URL | F1: Chi tiết | G1: Cách sửa
A2: Cao | B2: description_missing | C2: Thiếu meta description | D2: Trang | E2: https://adtek.agency/bao-chi/ | G2: Viết meta description 120 đến 155 ký tự trong Yoast, có từ khóa và lời kêu gọi.
A3: Cao | B3: description_missing | C3: Thiếu meta description | D3: Trang | E3: https://adtek.agency/blog/ | G3: Viết meta description 120 đến 155 ký tự trong Yoast, có từ khóa và lời kêu gọi.
A4: Cao | B4: description_missing | C4: Thiếu meta description | D4: Chuyên mục | E4: https://adtek.agency/category/campaign-marketing/ | G4: Viết meta description 120 đến 155 ký tự trong Yoast, có từ khóa và lời kêu gọi.
A5: Cao | B5: description_missing | C5: Thiếu meta description | D5: Chuyên mục | E5: https://adtek.agency/category/case-study/ | G5: Viết meta description 120 đến 155 ký tự trong Yoast, có từ khóa và lời kêu gọi.
A6: Cao | B6: description_missing | C6: Thiếu meta description | D6: Chuyên mục | E6: https://adtek.agency/category/crm/ | G6: Viết meta description 120 đến 155 ký tự trong Yoast, có từ khóa và lời kêu gọi.
A7: Cao | B7: description_missing | C7: Thiếu meta description | D7: Chuyên mục | E7: https://adtek.agency/category/digital-marketing/ | G7: Viết meta description 120 đến 155 ký tự trong Yoast, có từ khóa và lời kêu gọi.
A8: Cao | B8: description_missing | C8: Thiếu meta description | D8: Chuyên mục | E8: https://adtek.agency/category/growth-marketing/ | G8: Viết meta description 120 đến 155 ký tự trong Yoast, có từ khóa và lời kêu gọi.
A9: Cao | B9: description_missing | C9: Thiếu meta description | D9: Trang | E9: https://adtek.agency/contact/ | G9: Viết meta description 120 đến 155 ký tự trong Yoast, có từ khóa và lời kêu gọi.
A10: Cao | B10: description_missing | C10: Thiếu meta description | D10: Bài viết | E10: https://adtek.agency/customer-relationship-management-va-he-thong-crm/ | G10: Viết meta description 120 đến 155 ký tự trong Yoast, có từ khóa và lời kêu gọi.
A11: Cao | B11: description_missing | C11: Thiếu meta description | D11: Trang | E11: https://adtek.agency/en/about-us/ | G11: Viết meta description 120 đến 155 ký tự trong Yoast, có từ khóa và lời kêu gọi.
A12: Cao | B12: description_missing | C12: Thiếu meta description | D12: Giải pháp | E12: https://adtek.agency/en/solution/crm-consulting/ | G12: Viết meta description 120 đến 155 ký tự trong Yoast, có từ khóa và lời kêu gọi.
A13: Cao | B13: description_missing | C13: Thiếu meta description | D13: Giải pháp | E13: https://adtek.agency/en/solution/ecommerce-management/ | G13: Viết meta description 120 đến 155 ký tự trong Yoast, có từ khóa và lời kêu gọi.
... A186: Cao | B186: h1_missing | C186: Thiếu thẻ H1 | D186: Trang | E186: https://adtek.agency/solutions/ | G186: Thêm 1 tiêu đề H1 chứa từ khóa chính (thường cần sửa template của theme).
A187: Cao | B187: server_error | C187: Trang bị lỗi nghiêm trọng (PHP) giữa chừng | D187: Trang | E187: https://adtek.agency/vietnam-e-commerce-map/ | F187: HTTP 500, trang hiện "Đã có một lỗi nghiêm trọng trên trang web của bạn" | G187: Xem log lỗi trong Plesk > Logs, sửa template hoặc plugin gây lỗi.
A188: Cao | B188: sitemap_wrong_lang_url | C188: Sitemap ghi URL tiếng Anh thành URL tiếng Việt (thiếu /en/) | D188: Trang | E188: https://adtek.agency/page-sitemap.xml | F188: 8 trang tiếng Anh (FAQ, Contact, Blog...) bị ghi thành URL tiếng Việt, trùng lặp; bản /en/ không có trong sitemap | G188: Kiểm tra cài đặt WPML + Yoast sitemap, sau đó gửi lại sitemap trong Search Console.
A189: Trung bình | B189: description_duplicate | C189: Meta description trùng với trang khác | D189: Bài viết | E189: https://adtek.agency/case-study-slack-ung-dung-kinh-doanh-tang-truong-nhanh-nhat-trong-lich-su-phan-1/ | F189: Trong nghiên cứu về tăng trưởng, chúng ta sẽ cùng xem xét câu chuyện về Slack, c | G189: Viết mô tả riêng cho từng trang.
A190: Trung bình | B190: description_duplicate | C190: Meta description trùng với trang khác | D190: Bài viết | E190: https://adtek.agency/case-study-slack-ung-dung-kinh-doanh-tang-truong-nhanh-nhat-trong-lich-su-phan-2/ | F190: Trong nghiên cứu về tăng trưởng, chúng ta sẽ cùng xem xét câu chuyện về Slack, c | G190: Viết mô tả riêng cho từng trang.
A191: Trung bình | B191: h1_multiple | C191: Có nhiều hơn 1 thẻ H1 | D191: Bài viết | E191: https://adtek.agency/food-delivery-co-gi-hay-giua-cac-chien-dich-cua-gojek-baemin-va-grabfood/ | F191: Case Study: Có gì hay giữa các chiến dịc | Tìm hiểu chiến dịch marketing của Gojek | Câu chuyện về chiến dịch quảng cáo của B | Chiến lược Marketing giúp Grab định hình | G191: Giữ 1 H1, đổi các H1 còn lại thành H2.
A192: Trung bình | B192: h1_multiple | C192: Có nhiều hơn 1 thẻ H1 | D192: Giải pháp | E192: https://adtek.agency/solution/integrated-marketing-communication-imc/ | F192: Social Media | Social Media | Social Media | G192: Giữ 1 H1, đổi các H1 còn lại thành H2.
A193: Trung bình | B193: h1_multiple | C193: Có nhiều hơn 1 thẻ H1 | D193: Bài viết | E193: https://adtek.agency/tat-tan-tat-ve-nft-marketing/ | F193: Tất tần tật về NFT Marketing | Đặc điểm của NFT | NFT Creators | Cách thương hiệu thực hiện marketing cho | Ứng dụng của NFT đối với Marketing | NFT có đáng để đầu tư marketing không? | G193: Giữ 1 H1, đổi các H1 còn lại thành H2.
A194: Trung bình | B194: img_alt_missing | C194: Ảnh trong nội dung thiếu alt | D194: Trang | E194: https://adtek.agency/ | F194: 77 ảnh | G194: Điền Alt Text cho ảnh trong Thư viện, mô tả đúng nội dung ảnh.
A195: Trung bình | B195: img_alt_missing | C195: Ảnh trong nội dung thiếu alt | D195: Bài viết | E195: https://adtek.agency/24-cach-ung-dung-ai-de-nang-cao-hieu-qua-seo/ | F195: 37 ảnh | G195: Điền Alt Text cho ảnh trong Thư viện, mô tả đúng nội dung ảnh.
A196: Trung bình | B196: img_alt_missing | C196: Ảnh trong nội dung thiếu alt | D196: Bài viết | E196: https://adtek.agency/4-chien-luoc-d2c-doanh-nghiep-co-the-ap-dung-de-dan-dau-trong-nganh/ | F196: 20 ảnh | G196: Điền Alt Text cho ảnh trong Thư viện, mô tả đúng nội dung ảnh.
A197: Trung bình | B197: img_alt_missing | C197: Ảnh trong nội dung thiếu alt | D197: Bài viết | E197: https://adtek.agency/68-trieu-luot-truy-cap-tu-ai-he-lo-yeu-to-anh-huong-den-hien-thi-tren-ai-search/ | F197: 25 ảnh | G197: Điền Alt Text cho ảnh trong Thư viện, mô tả đúng nội dung ảnh.
A198: Trung bình | B198: img_alt_missing | C198: Ảnh trong nội dung thiếu alt | D198: Bài viết | E198: https://adtek.agency/ai-marketing-cach-thuc-hoat-dong-va-vi-du-cu-the/ | F198: 30 ảnh | G198: Điền Alt Text cho ảnh trong Thư viện, mô tả đúng nội dung ảnh.
... A303: Thấp | B303: description_long | C303: Meta description dài hơn 160 ký tự | D303: Bài viết | E303: https://adtek.agency/xu-huong-tan-dung-data-driven-cua-doanh-nghiep-nam-2025/ | F303: 248 ký tự | G303: Rút gọn còn 120 đến 155 ký tự.
A304: Thấp | B304: og_image_missing | C304: Thiếu ảnh chia sẻ mạng xã hội (og:image) | D304: Trang | E304: https://adtek.agency/ | G304: Đặt ảnh đại diện (featured image) hoặc ảnh Social trong Yoast.
A305: Thấp | B305: og_image_missing | C305: Thiếu ảnh chia sẻ mạng xã hội (og:image) | D305: Trang | E305: https://adtek.agency/bao-chi/ | G305: Đặt ảnh đại diện (featured image) hoặc ảnh Social trong Yoast.
A306: Thấp | B306: og_image_missing | C306: Thiếu ảnh chia sẻ mạng xã hội (og:image) | D306: Trang | E306: https://adtek.agency/blog/ | G306: Đặt ảnh đại diện (featured image) hoặc ảnh Social trong Yoast.
A307: Thấp | B307: og_image_missing | C307: Thiếu ảnh chia sẻ mạng xã hội (og:image) | D307: Chuyên mục | E307: https://adtek.agency/category/campaign-marketing/ | G307: Đặt ảnh đại diện (featured image) hoặc ảnh Social trong Yoast.
A308: Thấp | B308: og_image_missing | C308: Thiếu ảnh chia sẻ mạng xã hội (og:image) | D308: Chuyên mục | E308: https://adtek.agency/category/case-study/ | G308: Đặt ảnh đại diện (featured image) hoặc ảnh Social trong Yoast.
A309: Thấp | B309: og_image_missing | C309: Thiếu ảnh chia sẻ mạng xã hội (og:image) | D309: Chuyên mục | E309: https://adtek.agency/category/crm/ | G309: Đặt ảnh đại diện (featured image) hoặc ảnh Social trong Yoast.
A310: Thấp | B310: og_image_missing | C310: Thiếu ảnh chia sẻ mạng xã hội (og:image) | D310: Chuyên mục | E310: https://adtek.agency/category/digital-marketing/ | G310: Đặt ảnh đại diện (featured image) hoặc ảnh Social trong Yoast.
A311: Thấp | B311: og_image_missing | C311: Thiếu ảnh chia sẻ mạng xã hội (og:image) | D311: Chuyên mục | E311: https://adtek.agency/category/growth-marketing/ | G311: Đặt ảnh đại diện (featured image) hoặc ảnh Social trong Yoast.
A312: Thấp | B312: og_image_missing | C312: Thiếu ảnh chia sẻ mạng xã hội (og:image) | D312: Trang | E312: https://adtek.agency/contact/ | G312: Đặt ảnh đại diện (featured image) hoặc ảnh Social trong Yoast.
A313: Thấp | B313: og_image_missing | C313: Thiếu ảnh chia sẻ mạng xã hội (og:image) | D313: Trang | E313: https://adtek.agency/en/about-us/ | G313: Đặt ảnh đại diện (featured image) hoặc ảnh Social trong Yoast.
A314: Thấp | B314: og_image_missing | C314: Thiếu ảnh chia sẻ mạng xã hội (og:image) | D314: Trang | E314: https://adtek.agency/faq/ | G314: Đặt ảnh đại diện (featured image) hoặc ảnh Social trong Yoast.
A315: Thấp | B315: og_image_missing | C315: Thiếu ảnh chia sẻ mạng xã hội (og:image) | D315: Thuật ngữ | E315: https://adtek.agency/glossary/ | G315: Đặt ảnh đại diện (featured image) hoặc ảnh Social trong Yoast.
... A366: Thấp | B366: og_image_missing | C366: Thiếu ảnh chia sẻ mạng xã hội (og:image) | D366: Trang | E366: https://adtek.agency/solutions/ | G366: Đặt ảnh đại diện (featured image) hoặc ảnh Social trong Yoast.
...

Sheet Chi tiết URL
A1: URL | B1: Nhóm | C1: HTTP | D1: Title | E1: Độ dài title | F1: Meta description | G1: Độ dài description | H1: H1 | I1: Số H1 | J1: Số từ | K1: Ảnh thiếu alt (nội dung) | L1: Thời gian tải (giây) | M1: Canonical | N1: Robots
A2: https://adtek.agency/blog/ | B2: Trang | C2: 200 | D2: Bài Viết - Adtek | E2: =LEN(D2) | G2: =LEN(F2) | I2: 0 | J2: 554 | K2: 13 | L2: 0.78 | M2: https://adtek.agency/blog/ | N2: index, follow, max-image-preview:large, max-snippet:-1, max-video-preview:-1
A3: https://adtek.agency/growth-marketing-nhung-dieu-co-ban-doanh-nghiep-khong-the-bo-qua/ | B3: Bài viết | C3: 200 | D3: Growth Marketing & Những điều cơ bản doanh nghiệp không thể bỏ qua - Adtek | E3: =LEN(D3) | G3: =LEN(F3) | H3: Growth Marketing & Những điều cơ bản doanh nghiệp không thể bỏ qua | I3: 1 | J3: 12432 | K3: 23 | L3: 1 | M3: https://adtek.agency/growth-marketing-nhung-dieu-co-ban-doanh-nghiep-khong-the-bo-qua/ | N3: index, follow, max-image-preview:large, max-snippet:-1, max-video-preview:-1
A4: https://adtek.agency/marketing-analytics-trong-the-gioi-khong-con-cookie/ | B4: Bài viết | C4: 200 | D4: Marketing analytics trong thế giới không còn cookie - Adtek | E4: =LEN(D4) | G4: =LEN(F4) | H4: Marketing analytics trong thế giới không còn cookie | I4: 1 | J4: 2611 | K4: 20 | L4: 0.79 | M4: https://adtek.agency/marketing-analytics-trong-the-gioi-khong-con-cookie/ | N4: index, follow, max-image-preview:large, max-snippet:-1, max-video-preview:-1
A5: https://adtek.agency/gaming-industry-va-nfts-co-gi-dac-biet/ | B5: Bài viết | C5: 200 | D5: Gaming Industry và NFTs - Có gì đặc biệt? - Adtek | E5: =LEN(D5) | F5: NFT đang dần cách mạng hóa cách người chơi nghĩ về trò chơi trực tuyến và mua tài sản trong trò chơi. Trong khi ngành công nghiệp trò chơi toàn cầu tiếp tục phát triển trên tất cả các thị trường, lĩnh vực này vẫn được cấu trúc theo cách mang lại lợi ích cho các nhà phát triển trò chơi và duy trì giá trị nghiêng về 1 đối tượng cụ thể, nơi người chơi chi tiền để mở khóa quyền truy cập vào nội dung trong trò chơi và cấu hình trò chơi. Ngược lại, các trò chơi được xây dựng dựa trên blockchain và các ứng dụng phi tập trung (decentralized applications - dApps) cho phép người chơi nắm bắt tiện ích và giá trị của các giao dịch mua sắm trong trò chơi và mua lại tài sản một cách hiệu quả hơn. | G5: =LEN(F5) | H5: Gaming Industry và NFTs – Có gì đặc biệt? | I5: 1 | J5: 5881 | K5: 21 | L5: 3.76 | M5: https://adtek.agency/gaming-industry-va-nfts-co-gi-dac-biet/ | N5: index, follow, max-image-preview:large, max-snippet:-1, max-video-preview:-1
A6: https://adtek.agency/marketing-branding-trong-metaverse-co-gi/ | B6: Bài viết | C6: 200 | D6: Marketing, Branding trong Metaverse có gì? - Adtek | E6: =LEN(D6) | F6: Các thương hiệu ngày nay đang gấp gáp xây dựng bất động sản trong lĩnh vực ảo trước khi thị trường bắt đầu mở rộng hơn. Vì sao có thể nói rằng đưa doanh nghiệp tham gia vào Metaverse là cách thông minh, cách thực hiện chiến lược sẽ diễn ra như thế nào và mọi thứ trông như thế nào vào năm 2030. Hãy cùng tìm hiểu cách marketing cho các doanh nghiệp cũng như cơ hội và thách thức có thể gặp phải khi Marketing trên Metaverse. | G6: =LEN(F6) | H6: Marketing, Branding trong Metaverse có gì? | I6: 1 | J6: 5537 | K6: 20 | L6: 3.88 | M6: https://adtek.agency/marketing-branding-trong-metaverse-co-gi/ | N6: index, follow, max-image-preview:large, max-snippet:-1, max-video-preview:-1
A7: https://adtek.agency/heineken-thanh-cong-trong-chien-luoc-xay-dung-thuong-hieu-tren-metaverse-ra-sao/ | B7: Bài viết | C7: 200 | D7: Heineken thành công trong chiến lược xây dựng thương hiệu trên Metaverse ra sao? - Adtek | E7: =LEN(D7) | F7: Là thương hiệu sớm áp dụng Metaverse, có thể nói đây là một bước đi bất ngờ đối với Heineken. Về mặt giá trị, một thương hiệu Đồ uống tung ra một quán bar ảo nghe có vẻ không hợp lý. Bạn không thể (ít nhất là theo hiểu biết của chúng tôi) uống pixel. Thay vào đó, trong Khu vực Heineken Silver trên Decentraland, không có gì có thể mua được. Tuy nhiên, Heineken Silver - với hương vị ít đắng hơn và sảng khoái hơn - được nhắm mục tiêu vào genZ, mà đối tượng mục tiêu này ngày càng dành nhiều thời gian cho nhau trong thế giới Metaverse như Decentraland, Roblox và Sandbox. | G7: =LEN(F7) | H7: Heineken thành công trong chiến lược xây dựng thương hiệu trên Metaverse ra sao? | I7: 1 | J7: 3512 | K7: 19 | L7: 3.51 | M7: https://adtek.agency/heineken-thanh-cong-trong-chien-luoc-xay-dung-thuong-hieu-tren-metaverse-ra-sao/ | N7: index, follow, max-image-preview:large, max-snippet:-1, max-video-preview:-1
A8: https://adtek.agency/tat-tan-tat-ve-nft-marketing/ | B8: Bài viết | C8: 200 | D8: Tất tần tật về NFT Marketing - Adtek | E8: =LEN(D8) | F8: Nếu cơn sốt tiền ảo Bitcoin đã từng “làm mưa làm gió” trên thị trường thì hiện nay NFT đang trở thành hiện tượng thu hút sự quan tâm của nhiều nhà đầu tư. Vậy NFT là gì, nhà đầu tư đã thật sự hiểu về sản phẩm mới này hay chưa? Hãy cùng tìm hiểu qua bài viết dưới đây. | G8: =LEN(F8) | H8: Tất tần tật về NFT Marketing | Đặc điểm của NFT | NFT Creators | Cách thương hiệu thực hiện marketing cho NFT | Ứng dụng của NFT đối với Marketing | NFT có đáng để đầu tư marketing không? | I8: 6 | J8: 5135 | K8: 20 | L8: 3.51 | M8: https://adtek.agency/tat-tan-tat-ve-nft-marketing/ | N8: index, follow, max-image-preview:large, max-snippet:-1, max-video-preview:-1
A9: https://adtek.agency/funnel-to-flywheel-xu-huong-marketing-moi/ | B9: Bài viết | C9: 200 | D9: Funnel-to-Flywheel: Xu hướng Marketing mới? - Adtek | E9: =LEN(D9) | F9: Nếu mô hình phễu đặt khách hàng vào thế suy nghĩ sau khi hành động trong chiến lược marketing và bán hàng, Flywheel Marketing đặt khách hàng làm trọng tâm để giữ khách hàng hài lòng, cho phép họ giới thiệu và giúp công ty bán hàng. | G9: =LEN(F9) | H9: Funnel-to-Flywheel: Xu hướng Marketing mới? | I9: 1 | J9: 3201 | K9: 20 | L9: 3.21 | M9: https://adtek.agency/funnel-to-flywheel-xu-huong-marketing-moi/ | N9: index, follow, max-image-preview:large, max-snippet:-1, max-video-preview:-1
A10: https://adtek.agency/noi-tom-lai-flywheel-marketing-co-gi/ | B10: Bài viết | C10: 200 | D10: Nói tóm lại: Flywheel Marketing có gì? - Adtek | E10: =LEN(D10) | F10: Ý tưởng cơ bản đằng sau mô hình Flywheel hướng đến là khách hàng chính là những nhân viên bán hàng giỏi nhất của công ty. Nếu bạn làm họ hài lòng, họ sẽ nói với bạn bè của họ. Và nếu bạn giúp khách hàng tiềm năng dễ dàng tìm hiểu và mua hàng, những người đó sẽ mua hàng. Vậy ngoài những yếu tố đó, Flywheel Marketing còn có đặc điểm gì, hãy cùng Adtek tìm hiểu qua bài viết sau. | G10: =LEN(F10) | H10: Nói tóm lại: Flywheel Marketing có gì? | I10: 1 | J10: 5819 | K10: 18 | L10: 3.4 | M10: https://adtek.agency/noi-tom-lai-flywheel-marketing-co-gi/ | N10: index, follow, max-image-preview:large, max-snippet:-1, max-video-preview:-1
A11: https://adtek.agency/case-study-amazon-va-starbucks-da-ap-dung-flywheel-marketing-thanh-cong-nhu-the-nao/ | B11: Bài viết | C11: 200 | D11: Case Study: Amazon và Starbucks đã áp dụng Flywheel Marketing thành công như thế nào? - Adtek | E11: =LEN(D11) | F11: Trong nhiều năm qua các doanh nghiệp đã thực hiện chiến lược kinh doanh thông qua mô hình Phễu Marketing. Tuy nhiên đến hiện tại các công ty đã dần chuyển hướng sang Flywheel Marketing. Để hiểu rõ hơn về Flywheel Marketing, hãy cùng Adtek tìm hiểu case study của Amazon và Starbucks, cũng như bài học rút ra dành cho doanh nghiệp quan tâm đến Flywheel Marketing. | G11: =LEN(F11) | H11: Case Study: Amazon và Starbucks đã áp dụng Flywheel Marketing thành công như thế nào? | I11: 1 | J11: 6198 | K11: 18 | L11: 3.32 | M11: https://adtek.agency/case-study-amazon-va-starbucks-da-ap-dung-flywheel-marketing-thanh-cong-nhu-the-nao/ | N11: index, follow, max-image-preview:large, max-snippet:-1, max-video-preview:-1
A12: https://adtek.agency/case-study-slack-ung-dung-kinh-doanh-tang-truong-nhanh-nhat-trong-lich-su-phan-1/ | B12: Bài viết | C12: 200 | D12: Case Study: Slack - Ứng dụng kinh doanh tăng trưởng nhanh nhất trong lịch sử (Phần 1) - Adtek | E12: =LEN(D12) | F12: Trong nghiên cứu về tăng trưởng, chúng ta sẽ cùng xem xét câu chuyện về Slack, chiến lược khởi đầu và cơ bản của Slack trong việc làm chủ thế giới, cũng như cách họ xây dựng một nền tảng giúp thay đổi cách thức giao tiếp tại văn phòng.Người sáng lập kiêm Giám đốc điều hành Stewart Butterfield không lạ gì với các ứng dụng phát triển nhanh. Anh ấy đã xây dựng Flickr khoảng 10 năm trước khi bắt đầu Slack. | G12: =LEN(F12) | H12: Case Study: Slack – Ứng dụng kinh doanh tăng trưởng nhanh nhất trong lịch sử (Phần 1) | I12: 1 | J12: 6017 | K12: 23 | L12: 4.21 | M12: https://adtek.agency/case-study-slack-ung-dung-kinh-doanh-tang-truong-nhanh-nhat-trong-lich-su-phan-1/ | N12: index, follow, max-image-preview:large, max-snippet:-1, max-video-preview:-1
A13: https://adtek.agency/tat-tan-tat-ve-cdps-du-lieu-khach-hang-trong-thoi-dai-chuyen-doi-so/ | B13: Bài viết | C13: 200 | D13: Tất tần tật về CDPs - Dữ liệu khách hàng trong thời đại chuyển đổi số - Adtek | E13: =LEN(D13) | F13: Nền tảng dữ liệu khách hàng (CDP) hiện đang nhận được sự quan tâm lớn trong thời đại chuyển đổi số. Nhưng CDP có phải hệ thống hữu ích để quản lý dữ liệu, thúc đẩy hoạt động marketing hay không? Cùng Adtek tìm hiểu thông tin về CDP qua bài viết dưới đây. | G13: =LEN(F13) | H13: Tất tần tật về CDPs – Dữ liệu khách hàng trong thời đại chuyển đổi số | I13: 1 | J13: 5024 | K13: 19 | L13: 3.6 | M13: https://adtek.agency/tat-tan-tat-ve-cdps-du-lieu-khach-hang-trong-thoi-dai-chuyen-doi-so/ | N13: index, follow, max-image-preview:large, max-snippet:-1, max-video-preview:-1
A14: https://adtek.agency/cac-chuyen-gia-noi-gi-ve-cdps-tai-thi-truong-viet-nam/ | B14: Bài viết | C14: 200 | D14: Các chuyên gia nói gì về CDPs tại thị trường Việt Nam? - Adtek | E14: =LEN(D14) | F14: Bạn đã nghe về nền tảng dữ liệu khách hàng (CDP) và nhiều doanh nghiệp đang áp dụng hiện nay. Tuy nhiên tại Việt Nam, CDP dường như đang trở thành xu hướng mới. Hãy cùng xem các chuyên gia chia sẻ gì về CDP, marketing automation, AI, data,... qua bài viết dưới đây. | G14: =LEN(F14) | H14: Các chuyên gia nói gì về CDPs tại thị trường Việt Nam? | I14: 1 | J14: 5612 | K14: 19 | L14: 3.15 | M14: https://adtek.agency/cac-chuyen-gia-noi-gi-ve-cdps-tai-thi-truong-viet-nam/ | N14: index, follow, max-image-preview:large, max-snippet:-1, max-video-preview:-1
A15: https://adtek.agency/case-study-co-gi-dang-sau-su-thanh-cong-cua-pubg/ | B15: Bài viết | C15: 200 | D15: Case study: Có gì đằng sau sự thành công của PUBG? - Adtek | E15: =LEN(D15) | F15: PUBG đạt được sự thành công ấn tượng tại thị trường quốc tế và Việt Nam trong những năm qua nhờ vào các hoạt động đúng đắn, chiến lược marketing hợp lý. Vậy điều gì đã làm nên sự thành công của PUBG, cùng Adtek tìm hiểu qua bài viết sau đây! | G15: =LEN(F15) | H15: Case study: Có gì đằng sau sự thành công của PUBG? | I15: 1 | J15: 6364 | K15: 21 | L15: 3.09 | M15: https://adtek.agency/case-study-co-gi-dang-sau-su-thanh-cong-cua-pubg/ | N15: index, follow, max-image-preview:large, max-snippet:-1, max-video-preview:-1
A16: https://adtek.agency/xu-huong-tan-dung-data-driven-cua-doanh-nghiep-nam-2025/ | B16: Bài viết | C16: 200 | D16: Xu hướng tận dụng data driven của doanh nghiệp năm 2025 - Adtek | E16: =LEN(D16) | F16: Năm 2025, quy trình làm việc thông minh và tương tác liền mạch giữa con người và máy móc có thể sẽ trở thành tiêu chuẩn như bảng cân đối kế toán của công ty. Hầu hết nhân viên sẽ sử dụng dữ liệu để tối ưu hóa gần như mọi khía cạnh công việc của họ. | G16: =LEN(F16) | H16: Xu hướng tận dụng data driven của doanh nghiệp năm 2025 | I16: 1 | J16: 4079 | K16: 21 | L16: 3.05 | M16: https://adtek.agency/xu-huong-tan-dung-data-driven-cua-doanh-nghiep-nam-2025/ | N16: index, follow, max-image-preview:large, max-snippet:-1, max-video-preview:-1
... A20: https://adtek.agency/4-chien-luoc-d2c-doanh-nghiep-co-the-ap-dung-de-dan-dau-trong-nganh/ | B20: Bài viết | C20: 200 | D20: 4 chiến lược D2C doanh nghiệp có thể áp dụng để dẫn đầu trong ngành - Adtek | E20: =LEN(D20) | F20: Nhiều thương hiệu lớn đã thực hiện bước nhảy vọt về D2C Marketing và D2C hiện đang phát triển không ngừng kể từ năm 2021 và trong những năm tiếp theo. Tuy nhiên, mặc dù các rào cản gia nhập ngành khá thấp đối với các thương hiệu D2C startup, hãy nhớ rằng bạn sẽ phải cạnh tranh với những gã khổng lồ bán lẻ, những người đã tạo dựng được sự theo dõi từ một lượng khách hàng lớn. | G20: =LEN(F20) | H20: 4 chiến lược D2C doanh nghiệp có thể áp dụng để dẫn đầu trong ngành | I20: 1 | J20: 3302 | K20: 20 | L20: 3.04 | M20: https://adtek.agency/4-chien-luoc-d2c-doanh-nghiep-co-the-ap-dung-de-dan-dau-trong-nganh/ | N20: index, follow, max-image-preview:large, max-snippet:-1, max-video-preview:-1
A21: https://adtek.agency/customer-relationship-management-va-he-thong-crm/ | B21: Bài viết | C21: 200 | D21: Customer relationship management và Hệ thống CRM - Adtek | E21: =LEN(D21) | G21: =LEN(F21) | H21: Customer relationship management và Hệ thống CRM | I21: 1 | J21: 7496 | K21: 21 | L21: 3.07 | M21: https://adtek.agency/customer-relationship-management-va-he-thong-crm/ | N21: index, follow, max-image-preview:large, max-snippet:-1, max-video-preview:-1
A22: https://adtek.agency/ai-marketing-cach-thuc-hoat-dong-va-vi-du-cu-the/ | B22: Bài viết | C22: 200 | D22: AI marketing: Cách thức hoạt động và ví dụ cụ thể - Adtek | E22: =LEN(D22) | F22: AI marketing là gì? Khám phá lợi ích, cách ứng dụng thực tế và công cụ AI giúp tối ưu chiến dịch, tăng hiệu quả và ROI nhanh chóng. | G22: =LEN(F22) | H22: AI marketing: Cách thức hoạt động và ví dụ cụ thể | I22: 1 | J22: 3702 | K22: 30 | L22: 3.04 | M22: https://adtek.agency/ai-marketing-cach-thuc-hoat-dong-va-vi-du-cu-the/ | N22: index, follow, max-image-preview:large, max-snippet:-1, max-video-preview:-1
A23: https://adtek.agency/lam-the-nao-de-toi-uu-hoa-toan-bo-pheu-marketing-voi-ai/ | B23: Bài viết | C23: 200 | D23: Làm thế nào để tối ưu hóa toàn bộ phễu marketing với AI? - Adtek | E23: =LEN(D23) | F23: Tối ưu phễu marketing với AI: Cách cá nhân hóa hành trình, tối ưu hóa phễu, nâng cao chuyển đổi và xây dựng hệ thống vận hành hiệu quả. | G23: =LEN(F23) | H23: Làm thế nào để tối ưu hóa toàn bộ phễu marketing với AI? | I23: 1 | J23: 4064 | K23: 29 | L23: 3.13 | M23: https://adtek.agency/lam-the-nao-de-toi-uu-hoa-toan-bo-pheu-marketing-voi-ai/ | N23: index, follow, max-image-preview:large, max-snippet:-1, max-video-preview:-1
A24: https://adtek.agency/ung-dung-ai-trong-seo-va-content-marketing-ban-dong-hanh-hay-doi-thu-tiem-an/ | B24: Bài viết | C24: 200 | D24: Ứng dụng AI trong SEO và Content Marketing: Bạn đồng hành hay đối thủ tiềm ẩn - Adtek | E24: =LEN(D24) | F24: Khám phá cách AI đang thay đổi SEO và Content Marketing, từ tạo nội dung, tối ưu SEO đến mở rộng chiến lược digital marketing. | G24: =LEN(F24) | H24: Ứng dụng AI trong SEO và Content Marketing: Bạn đồng hành hay đối thủ tiềm ẩn | I24: 1 | J24: 3891 | K24: 16 | L24: 3 | M24: https://adtek.agency/ung-dung-ai-trong-seo-va-content-marketing-ban-dong-hanh-hay-doi-thu-tiem-an/ | N24: index, follow, max-image-preview:large, max-snippet:-1, max-video-preview:-1
A25: https://adtek.agency/khi-content-khong-con-la-vua-goc-nhin-moi-ve-content-marketing/ | B25: Bài viết | C25: 200 | D25: Khi Content không còn là Vua trong thời đại AI: Góc nhìn mới về Content Marketing - Adtek | E25: =LEN(D25) | F25: Content is King liệu đã lỗi thời? Khám phá chiến lược content marketing mới để tạo khác biệt và tăng hiệu quả khi xuất bản nội dung sau 2025. | G25: =LEN(F25) | H25: Khi Content không còn là Vua trong thời đại AI: Góc nhìn mới về Content Marketing | I25: 1 | J25: 2376 | K25: 16 | L25: 3.04 | M25: https://adtek.agency/khi-content-khong-con-la-vua-goc-nhin-moi-ve-content-marketing/ | N25: index, follow, max-image-preview:large, max-snippet:-1, max-video-preview:-1
A26: https://adtek.agency/toan-canh-ai-marketing-6-goc-nhin-moi-tu-chuyen-gia-dau-nganh/ | B26: Bài viết | C26: 200 | D26: Toàn cảnh AI marketing: 6 góc nhìn mới từ chuyên gia đầu ngành - Adtek | E26: =LEN(D26) | F26: Khám phá 6 insight nổi bật về AI trong marketing và xu hướng đầu tư AI của đội ngũ marketer toàn cầu khi AI lên ngôi. | G26: =LEN(F26) | H26: Toàn cảnh AI marketing: 6 góc nhìn mới từ chuyên gia đầu ngành | I26: 1 | J26: 2107 | K26: 22 | L26: 3.46 | M26: https://adtek.agency/toan-canh-ai-marketing-6-goc-nhin-moi-tu-chuyen-gia-dau-nganh/ | N26: index, follow, max-image-preview:large, max-snippet:-1, max-video-preview:-1
A27: https://adtek.agency/24-cach-ung-dung-ai-de-nang-cao-hieu-qua-seo/ | B27: Bài viết | C27: 200 | D27: 24 cách ứng dụng AI để nâng cao hiệu quả SEO - Adtek | E27: =LEN(D27) | F27: Khám phá 24 cách ứng dụng AI SEO trong việc nghiên cứu từ khóa, tối ưu content, internal link, UX và tự động hóa quy trình hiệu quả hơn. | G27: =LEN(F27) | H27: 24 cách ứng dụng AI để nâng cao hiệu quả SEO | I27: 1 | J27: 4014 | K27: 37 | L27: 3.23 | M27: https://adtek.agency/24-cach-ung-dung-ai-de-nang-cao-hieu-qua-seo/ | N27: index, follow, max-image-preview:large, max-snippet:-1, max-video-preview:-1
A28: https://adtek.agency/ung-dung-generative-ai-trong-marketing-cong-cu-ho-tro-vi-du-thuc-te-va-case-study-dot-pha/ | B28: Bài viết | C28: 200 | D28: Ứng dụng Generative AI trong Marketing: Công cụ hỗ trợ, ví dụ thực tế và case study đột phá - Adtek | E28: =LEN(D28) | F28: Cách ứng dụng Generative AI trong Marketing: công cụ nổi bật, ví dụ thực tế và case study giúp tăng ROI, tự động hóa, cá nhân hóa hiệu quả cho doanh nghiệp | G28: =LEN(F28) | H28: Ứng dụng Generative AI trong Marketing: Công cụ hỗ trợ, ví dụ thực tế và case study đột phá | I28: 1 | J28: 7535 | K28: 37 | L28: 3.71 | M28: https://adtek.agency/ung-dung-generative-ai-trong-marketing-cong-cu-ho-tro-vi-du-thuc-te-va-case-study-dot-pha/ | N28: index, follow, max-image-preview:large, max-snippet:-1, max-video-preview:-1
A29: https://adtek.agency/ai-marketing-case-studies-2026-kham-pha-chien-dich-thuc-te-mang-lai-roi-vuot-troi/ | B29: Bài viết | C29: 200 | D29: AI Marketing Case Studies 2026: Khám phá chiến dịch thực tế mang lại ROI vượt trội - Adtek | E29: =LEN(D29) | F29: Thương hiệu dẫn đầu đang dùng AI thế nào? Khám phá case study thực tế, kết quả đạt được và rút ra bài học triển khai. | G29: =LEN(F29) | H29: AI Marketing Case Studies 2026: Khám phá chiến dịch thực tế mang lại ROI vượt trội | I29: 1 | J29: 3791 | K29: 30 | L29: 3.77 | M29: https://adtek.agency/ai-marketing-case-studies-2026-kham-pha-chien-dich-thuc-te-mang-lai-roi-vuot-troi/ | N29: index, follow, max-image-preview:large, max-snippet:-1, max-video-preview:-1
A30: https://adtek.agency/case-study-cam-nang-ung-dung-ai-danh-cho-marketer-nganh-thoi-trang/ | B30: Bài viết | C30: 200 | D30: Case Study: Cẩm nang ứng dụng AI dành cho marketer ngành thời trang - Adtek | E30: =LEN(D30) | F30: Khám phá cách các thương hiệu ứng dụng AI Marketing ngành thời trang , cá nhân hóa trải nghiệm và gia tăng doanh thu. | G30: =LEN(F30) | H30: Case Study: Cẩm nang ứng dụng AI dành cho marketer ngành thời trang | I30: 1 | J30: 8795 | K30: 39 | L30: 3.58 | M30: https://adtek.agency/case-study-cam-nang-ung-dung-ai-danh-cho-marketer-nganh-thoi-trang/ | N30: index, follow, max-image-preview:large, max-snippet:-1, max-video-preview:-1
A31: https://adtek.agency/toan-canh-buc-tranh-marketing-thanh-cong-trong-thoi-dai-ai-den-tu-tieng-noi-rieng-cua-thuong-hieu-va-su-tham-gia-cua-con-nguoi/ | B31: Bài viết | C31: 200 | D31: Toàn cảnh bức tranh Marketing: Thành công trong thời đại AI đến từ tiếng nói riêng của thương hiệu và sự tham gia của con người - Adtek | E31: =LEN(D31) | F31: Thành công trong thời đại AI marketing 2026 đến từ tiếng nói thương hiệu riêng và sức mạnh con người. Khám phá xu hướng, insight thực tế và rút ra chiến lược từ báo cáo. | G31: =LEN(F31) | H31: Toàn cảnh bức tranh Marketing: Thành công trong thời đại AI đến từ tiếng nói riêng của thương hiệu và sự tham gia của con người | I31: 1 | J31: 8293 | K31: 34 | L31: 3.35 | M31: https://adtek.agency/toan-canh-buc-tranh-marketing-thanh-cong-trong-thoi-dai-ai-den-tu-tieng-noi-rieng-cua-thuong-hieu-va-su-tham-gia-cua-con-nguoi/ | N31: index, follow, max-image-preview:large, max-snippet:-1, max-video-preview:-1
A32: https://adtek.agency/68-trieu-luot-truy-cap-tu-ai-he-lo-yeu-to-anh-huong-den-hien-thi-tren-ai-search/ | B32: Bài viết | C32: 200 | D32: 68 Triệu lượt truy cập từ AI hé lộ yếu tố ảnh hưởng đến hiển thị trên AI Search - Adtek | E32: =LEN(D32) | F32: Nghiên cứu 68 triệu lượt truy cập AI crawler tiết lộ yếu tố tác động đến khả năng hiển thị website trên AI Search | G32: =LEN(F32) | H32: 68 Triệu lượt truy cập từ AI hé lộ yếu tố ảnh hưởng đến hiển thị trên AI Search | I32: 1 | J32: 2987 | K32: 25 | L32: 3.2 | M32: https://adtek.agency/68-trieu-luot-truy-cap-tu-ai-he-lo-yeu-to-anh-huong-den-hien-thi-tren-ai-search/ | N32: index, follow, max-image-preview:large, max-snippet:-1, max-video-preview:-1
A33: https://adtek.agency/ | B33: Trang | C33: 200 | D33: Adtek - Growth Marketing Agency | Brand Commerce | SEO | E33: =LEN(D33) | F33: Adtek cung cấp chiến lược và giải pháp marketing tổng thể: Brand Commerce, Lead Generation, SEO... giúp doanh nghiệp bứt phá tăng trưởng. | G33: =LEN(F33) | H33: Growth Marketing Agency | I33: 1 | J33: 1308 | K33: 77 | L33: 1.01 | M33: https://adtek.agency/ | N33: index, follow, max-image-preview:large, max-snippet:-1, max-video-preview:-1
A34: https://adtek.agency/recruitments/ | B34: Trang | C34: 200 | D34: Tuyển dụng - Adtek | E34: =LEN(D34) | G34: =LEN(F34) | I34: 0 | J34: 44 | K34: 1 | L34: 0.79 | M34: https://adtek.agency/recruitments/ | N34: index, follow, max-image-preview:large, max-snippet:-1, max-video-preview:-1
A35: https://adtek.agency/faq/ | B35: Trang | C35: 200 | D35: FAQ - Adtek | E35: =LEN(D35) | G35: =LEN(F35) | I35: 0 | J35: 473 | K35: 0 | L35: 0.79 | M35: https://adtek.agency/faq/ | N35: index, follow, max-image-preview:large, max-snippet:-1, max-video-preview:-1
A36: https://adtek.agency/resources-glossary/ | B36: Trang | C36: 200 | D36: Thuật ngữ marketing - Adtek | E36: =LEN(D36) | G36: =LEN(F36) | I36: 0 | J36: 266 | K36: 0 | L36: 0.8 | M36: https://adtek.agency/resources-glossary/ | N36: index, follow, max-image-preview:large, max-snippet:-1, max-video-preview:-1
A37: https://adtek.agency/resources-report/ | B37: Trang | C37: 200 | D37: Báo cáo - Adtek | E37: =LEN(D37) | G37: =LEN(F37) | I37: 0 | J37: 123 | K37: 1 | L37: 0.78 | M37: https://adtek.agency/resources-report/ | N37: index, follow, max-image-preview:large, max-snippet:-1, max-video-preview:-1
A38: https://adtek.agency/vietnam-e-commerce-map/ | B38: Trang | C38: 500 | D38: Bản đồ các ngành - AdtekWordPress › Lỗi | E38: =LEN(D38) | G38: =LEN(F38) | I38: 0 | J38: 391 | K38: 0 | L38: 3.94 | M38: https://adtek.agency/vietnam-e-commerce-map/ | N38: noindex, follow
A39: https://adtek.agency/contact/ | B39: Trang | C39: 200 | D39: Liên Hệ - Adtek | E39: =LEN(D39) | G39: =LEN(F39) | I39: 0 | J39: 166 | K39: 3 | L39: 0.79 | M39: https://adtek.agency/contact/ | N39: index, follow, max-image-preview:large, max-snippet:-1, max-video-preview:-1
A40: https://adtek.agency/en/about-us/ | B40: Trang | C40: 200 | D40: About Us - Adtek Growth Marketing Agency | E40: =LEN(D40) | G40: =LEN(F40) | H40: Problem-solving is our DNA. | I40: 1 | J40: 226 | K40: 17 | L40: 3.19 | M40: https://adtek.agency/en/about-us/ | N40: index, follow, max-image-preview:large, max-snippet:-1, max-video-preview:-1
A41: https://adtek.agency/bao-chi/ | B41: Trang | C41: 200 | D41: Báo chí - Adtek | E41: =LEN(D41) | G41: =LEN(F41) | I41: 0 | J41: 4 | K41: 0 | L41: 0.78 | M41: https://adtek.agency/bao-chi/ | N41: index, follow, max-image-preview:large, max-snippet:-1, max-video-preview:-1
A42: https://adtek.agency/solutions/ | B42: Trang | C42: 200 | D42: Giải pháp - Adtek | E42: =LEN(D42) | G42: =LEN(F42) | I42: 0 | J42: 445 | K42: 36 | L42: 0.8 | M42: https://adtek.agency/solutions/ | N42: index, follow, max-image-preview:large, max-snippet:-1, max-video-preview:-1
A43: https://adtek.agency/recruitment/ | B43: Tuyển dụng | C43: 200 | D43: Recruitment Archive - Adtek | E43: =LEN(D43) | G43: =LEN(F43) | I43: 0 | J43: 106 | K43: 0 | L43: 3.09 | M43: https://adtek.agency/recruitment/ | N43: index, follow, max-image-preview:large, max-snippet:-1, max-video-preview:-1
...

Sheet Link hỏng
A1: Link | B1: HTTP | C1: Số trang chứa link | D1: Ví dụ trang chứa link
A2: Không phát hiện link nội bộ hỏng
